Workbook
Name __________a121: {"'ICo.'!$J$12:$K$20"}
Name _________a121: {"'ICo.'!$J$12:$K$20"}
Name ________a121: {"'ICo.'!$J$12:$K$20"}
Name _______a121: {"'ICo.'!$J$12:$K$20"}
Name _______DCF1: {#N/A,#N/A,FALSE,"DCF Summary";#N/A,#N/A,FALSE,"Casema";#N/A,#N/A,FALSE,"Casema NoTel";#N/A,#N/A,FALSE,"UK";#N/A,#N/A,FALSE,"RCF";#N/A,#N/A,FALSE,"Intercable CZ";#N/A,#N/A,FALSE,"Interkabel P"}
Name ______a121: {"'ICo.'!$J$12:$K$20"}
Name ______DCF1: {#N/A,#N/A,FALSE,"DCF Summary";#N/A,#N/A,FALSE,"Casema";#N/A,#N/A,FALSE,"Casema NoTel";#N/A,#N/A,FALSE,"UK";#N/A,#N/A,FALSE,"RCF";#N/A,#N/A,FALSE,"Intercable CZ";#N/A,#N/A,FALSE,"Interkabel P"}
Name ______fdv2: {"quarterly",#N/A,FALSE,"Income Statement";#N/A,#N/A,FALSE,"print segment";#N/A,#N/A,FALSE,"Balance Sheet";#N/A,#N/A,FALSE,"Annl Inc";#N/A,#N/A,FALSE,"Cash Flow"}
Name ______OCT334: #REF!
Name _____a121: {"'ICo.'!$J$12:$K$20"}
Name _____c: {#N/A,#N/A,FALSE,"Layout Cash Flow"}
Name _____DCF1: {#N/A,#N/A,FALSE,"DCF Summary";#N/A,#N/A,FALSE,"Casema";#N/A,#N/A,FALSE,"Casema NoTel";#N/A,#N/A,FALSE,"UK";#N/A,#N/A,FALSE,"RCF";#N/A,#N/A,FALSE,"Intercable CZ";#N/A,#N/A,FALSE,"Interkabel P"}
Name _____dcf2: {#N/A,#N/A,FALSE,"DCF Summary";#N/A,#N/A,FALSE,"Casema";#N/A,#N/A,FALSE,"Casema NoTel";#N/A,#N/A,FALSE,"UK";#N/A,#N/A,FALSE,"RCF";#N/A,#N/A,FALSE,"Intercable CZ";#N/A,#N/A,FALSE,"Interkabel P"}
Name _____fdv2: {"quarterly",#N/A,FALSE,"Income Statement";#N/A,#N/A,FALSE,"print segment";#N/A,#N/A,FALSE,"Balance Sheet";#N/A,#N/A,FALSE,"Annl Inc";#N/A,#N/A,FALSE,"Cash Flow"}
Name _____key2: #REF!
Name _____OCT334: #REF!
Name ____a121: {"'ICo.'!$J$12:$K$20"}
Name ____c: {#N/A,#N/A,FALSE,"Layout Cash Flow"}
Name ____cc1: {"'I-1 and I-2'!$A$1:$G$190"}
Name ____DAT1: #REF!
Name ____DAT2: #REF!
Name ____DAT3: #REF!
Name ____DAT4: #REF!
Name ____DAT5: #REF!
Name ____DAT6: #REF!
Name ____DAT7: #REF!
Name ____DCF1: {#N/A,#N/A,FALSE,"DCF Summary";#N/A,#N/A,FALSE,"Casema";#N/A,#N/A,FALSE,"Casema NoTel";#N/A,#N/A,FALSE,"UK";#N/A,#N/A,FALSE,"RCF";#N/A,#N/A,FALSE,"Intercable CZ";#N/A,#N/A,FALSE,"Interkabel P"}
Name ____dcf2: {#N/A,#N/A,FALSE,"DCF Summary";#N/A,#N/A,FALSE,"Casema";#N/A,#N/A,FALSE,"Casema NoTel";#N/A,#N/A,FALSE,"UK";#N/A,#N/A,FALSE,"RCF";#N/A,#N/A,FALSE,"Intercable CZ";#N/A,#N/A,FALSE,"Interkabel P"}
Name ____dd1: {"'I-1 and I-2'!$A$1:$G$190"}
Name ____fdv2: {"quarterly",#N/A,FALSE,"Income Statement";#N/A,#N/A,FALSE,"print segment";#N/A,#N/A,FALSE,"Balance Sheet";#N/A,#N/A,FALSE,"Annl Inc";#N/A,#N/A,FALSE,"Cash Flow"}
Name ____Grp16: {#N/A,#N/A,FALSE,"PMTABB";#N/A,#N/A,FALSE,"PMTABB"}
Name ____key1: '[1]#REF'!#REF!
Name ____key2: #REF!
Name ____OCT334: #REF!
Name ____raj1234: {"","","'Curves'!$V$3","'Curves'!$W$3","","","","","",""}
Name ____sm1: {"'I-1 and I-2'!$A$1:$G$190"}
Name ___a121: {"'ICo.'!$J$12:$K$20"}
Name ___c: {#N/A,#N/A,FALSE,"Layout Cash Flow"}
Name ___cc1: {"'I-1 and I-2'!$A$1:$G$190"}
Name ___DAT1: #REF!
Name ___DAT2: #REF!
Name ___DAT3: #REF!
Name ___DAT4: #REF!
Name ___DAT5: #REF!
Name ___DAT6: #REF!
Name ___DAT7: #REF!
Name ___DCF1: {#N/A,#N/A,FALSE,"DCF Summary";#N/A,#N/A,FALSE,"Casema";#N/A,#N/A,FALSE,"Casema NoTel";#N/A,#N/A,FALSE,"UK";#N/A,#N/A,FALSE,"RCF";#N/A,#N/A,FALSE,"Intercable CZ";#N/A,#N/A,FALSE,"Interkabel P"}
Name ___dcf2: {#N/A,#N/A,FALSE,"DCF Summary";#N/A,#N/A,FALSE,"Casema";#N/A,#N/A,FALSE,"Casema NoTel";#N/A,#N/A,FALSE,"UK";#N/A,#N/A,FALSE,"RCF";#N/A,#N/A,FALSE,"Intercable CZ";#N/A,#N/A,FALSE,"Interkabel P"}
Name ___dd1: {"'I-1 and I-2'!$A$1:$G$190"}
Name ___fdv2: {"quarterly",#N/A,FALSE,"Income Statement";#N/A,#N/A,FALSE,"print segment";#N/A,#N/A,FALSE,"Balance Sheet";#N/A,#N/A,FALSE,"Annl Inc";#N/A,#N/A,FALSE,"Cash Flow"}
Name ___fy97: {#N/A,#N/A,FALSE,"FY97";#N/A,#N/A,FALSE,"FY98";#N/A,#N/A,FALSE,"FY99";#N/A,#N/A,FALSE,"FY00";#N/A,#N/A,FALSE,"FY01"}
Name ___Grp16: {#N/A,#N/A,FALSE,"PMTABB";#N/A,#N/A,FALSE,"PMTABB"}
Name ___key1: '[1]#REF'!#REF!
Name ___key2: #REF!
Name ___OCT334: #REF!
Name ___r: {"consolidated",#N/A,FALSE,"Sheet1";"cms",#N/A,FALSE,"Sheet1";"fse",#N/A,FALSE,"Sheet1"}
Name ___raj1234: {"","","'Curves'!$V$3","'Curves'!$W$3","","","","","",""}
Name ___sm1: {"'I-1 and I-2'!$A$1:$G$190"}
Name ___thinkcell11wvTEL6W0W2zDrq5o.quA: #REF!
Name ___wrn1: {#N/A,#N/A,FALSE,"DCF";#N/A,#N/A,FALSE,"WACC";#N/A,#N/A,FALSE,"Sales_EBIT";#N/A,#N/A,FALSE,"Capex_Depreciation";#N/A,#N/A,FALSE,"WC";#N/A,#N/A,FALSE,"Interest";#N/A,#N/A,FALSE,"Assumptions"}

Sheet Charts
A1: SoftBank Group Corp.
A2: year end March ¥m
J4: SBG NAV mix vs. discount to NAV: | S4: Arm % upside/(downside) to March '26 | W4: 0.1 | AS4: % | AT4: %
AR5: 2030 | AS5: 2030 | AT5: 2050 | AV5: Today
J6: Today: | N6: June '24 net equity holdings | O6: % | P6: June '24 NAV | Q6: SBG market cap. today | S6: SBG 5-10yrs: | W6: '30E net equity holdings | X6: % | Y6: '30E NAV | Z6: SBG market cap. '30E | AO6: Arm + AI infrastructure | AR6: =W7 -> 198.35 | AS6: =MROUND(AR6/SUM($AR$6:$AR$11), 0.5%) -> #NUM! | AT6: 0.4 | AV6: =N7/SUM($N$7:$N$15) -> 0.54947368
J7: Arm | N7: =MROUND('Valuation & SBG NAV'!$BG$64, 0.05) -> 130.5 | O7: =N7/$N$20 -> 0.59602649 | P7: =$N$20 -> 218.95 | Q7: =$N$24 -> 149 | S7: Arm | W7: =MROUND(((N7+12)*(1-$W$4))*(1.1)^(3.75), 0.05)+15 -> 198.35 | X7: =W7/$W$20 -> #NUM! | Y7: =$W$20 -> #NUM! | Z7: =$W$24 -> #NUM! | AB7: = using 3.75yrs of Arm expected return on equity from March '26 share price + $15bn Arm accelerator investment. | AO7: Vision Funds | AR7: =SUM(W8:W10) -> 80.4 | AS7: =MROUND(AR7/SUM($AR$6:$AR$11), 0.5%) -> #NUM! | AT7: 0 | AV7: =SUM(N8:N10)/$N$17 -> 0.24168421
J8: SVF1 | N8: =MROUND('Valuation & SBG NAV'!$BG$56, 0.05) -> 24.1 | O8: =N8/$N$20 -> 0.11007079 | S8: SVF1 | W8: 0 | X8: =W8/$W$20 -> #NUM! | AB8: = initial fund life to November '29. | AO8: Domestic telcos + Japanese LLM | AR8: =W11 -> 26.65 | AS8: =MROUND(AR8/SUM($AR$6:$AR$11), 0.5%) -> #NUM! | AT8: 0.15 | AV8: =N11/$N$17 -> 0.083578947
J9: SVF2 | N9: =MROUND('Valuation & SBG NAV'!$BG$59, 0.05) -> 26.95 | O9: =N9/$N$20 -> 0.12308746 | S9: SVF2 | W9: =MROUND(N9*'SVF2'!$BX$11/'SVF2'!$AR$11, 0.05) -> 65.05 | X9: =W9/$W$20 -> #NUM! | AB9: = initial fund life to October '32. | AO9: International telcos | AR9: =SUM(W12:W13) -> 6.1 | AS9: =MROUND(AR9/SUM($AR$6:$AR$11), 0.5%) -> #NUM! | AT9: 0
J10: LatAm Funds | N10: =MROUND('Valuation & SBG NAV'!$BG$60, 0.05) -> 6.35 | O10: =N10/$N$20 -> 0.029002055 | S10: LatAm Funds | W10: =MROUND(N10*W9/N9, 0.05) -> 15.35 | X10: =W10/$W$20 -> #NUM! | AB10: = using SVF2 equivalent timeline. | AO10: Robotics | AR10: =W14 -> #NUM! | AS10: =MROUND(AR10/SUM($AR$6:$AR$11), 0.5%) -> #NUM! | AT10: 0.35
J11: SoftBank Corp. | N11: =MROUND('Valuation & SBG NAV'!$BG$55, 0.05) -> 19.85 | O11: =N11/$N$20 -> 0.090659968 | S11: SoftBank Corp. | W11: =MROUND(N11*(1+'Valuation & SBG NAV'!$BI$147)^(5.5), 0.05) -> 26.65 | X11: =W11/$W$20 -> #NUM! | AB11: = using 5.5yrs of SoftBank KK expected return on equity. | AO11: Others | AR11: =W15 -> 18 | AS11: =MROUND(AR11/SUM($AR$6:$AR$11), 0.5%) -> #NUM! | AT11: 0.1
J12: T-Mobile US | N12: =MROUND('Valuation & SBG NAV'!$BG$62, 0.05) -> 15 | O12: =N12/$N$20 -> 0.068508792 | S12: T-Mobile US | W12: =MROUND(N12*0.33, 0.05) -> 4.95 | X12: =W12/$W$20 -> #NUM! | AB12: = assume exposure more than halved by end of decade: non-core telcos assets.
J13: Deutsche Telekom | N13: =MROUND('Valuation & SBG NAV'!$BG$63, 0.05) -> 2.3 | O13: =N13/$N$20 -> 0.010504681 | S13: Deutsche Telekom | W13: =MROUND(N13*0.5, 0.05) -> 1.15 | X13: =W13/$W$20 -> #NUM! | AB13: = assume exposure more than halved by end of decade: non-core telcos assets.
J14: Alibaba | N14: =MROUND('Valuation & SBG NAV'!$BG$54, 0.05) -> 0.05 | O14: =N14/$N$20 -> 0.00022836264 | S14: Robotics + Japanese LLM | W14: =W35 -> #NUM! | X14: =W14/$W$20 -> #NUM! | AB14: = assumes SVF + non-core telcos sales reinvested in Robotics + Japanese LLM at 5% equity return: less $10bn capital returns and $10bn Arm accelerator investment.
J15: Others | N15: =MROUND('Valuation & SBG NAV'!$BG$65, 0.05) -> 12.4 | O15: =N15/$N$20 -> 0.056633935 | S15: Others | W15: =W36 -> 18 | X15: =W15/$W$20 -> #NUM! | AB15: = assumes 7% equity return on Other assets: less $10bn capital returns.
S16: Capital returns to shareholders | W16: =MROUND(W19-N19, 0.5) -> #NUM! | X16: =W16/$W$20 -> #NUM! | Z16: =W16 -> #NUM!
J17: SBG equity holdings net of asset-backed financing | N17: =SUM(N7:N15) -> 237.5 | S17: SBG equity holdings net of asset-backed financing | W17: =SUM(W7:W13)+SUM(W35:W36) -> #NUM!
J19: Less: SBG TopCo net debt | N19: =MROUND('Valuation & SBG NAV'!$BG$71, 0.05) -> 18.55 | S19: Less: SBG TopCo net debt | W19: =MROUND(W17*W22, 0.05) -> #NUM!
J20: SBG NAV as reported | N20: =N17-N19 -> 218.95 | S20: SBG NAV as reported | W20: =W17-W19 -> #NUM!
J22: LTV | N22: =N19/N17 -> 0.078105263 | S22: LTV | W22: 0.15 | AB22: = SBG calls out an average LTV of 14.5% over last 4-5yrs.
J24: vs. SBG market cap. $bn | N24: =MROUND(FP!$D$13/1000, 0.05) -> 149 | S24: vs. SBG market cap. $bn | W24: =MROUND(W20*(1-W25), 0.05) -> #NUM!
J25: % discount to NAV | N25: =1-(N24/N20) -> 0.31947933 | S25: % discount to NAV | W25: 0.25
S27: Assets monetised by end of decade: | X27: % equity return:
S28: SVF1 | W28: =N8-W8 -> 24.1 | X28: ='SVF1'!$AS$12 -> 0.035 | Z28: =X28*W28/$W$33 -> -0.071483051
S29: SVF2 | W29: =N9-W9 -> -38.1 | X29: ='SVF2'!$AS$14 -> 0.05 | Z29: =X29*W29/$W$33 -> 0.16144068
S30: LatAm Funds | W30: =N10-W10 -> -9 | X30: ='SVF Segment'!$AP$983 -> 0.09 | Z30: =X30*W30/$W$33 -> 0.068644068
S31: T-Mobile US | W31: =N12-W12 -> 10.05 | X31: ='Investment Business Of HoldCo'!$AS$138 -> 0.08 | Z31: =X31*W31/$W$33 -> -0.068135593
S32: Deutsche Telekom | W32: =N13-W13 -> 1.15 | X32: ='Investment Business Of HoldCo'!$AS$187 -> 0.08 | Z32: =X32*W32/$W$33 -> -0.0077966102
S33: Total | W33: =SUM(W28:W32) -> -11.8 | X33: =SUM(Z28:Z32) -> 0.082669492
S35: Total value of monetised assets at 2030 = | W35: =MROUND((SUM(N8:N10, N12:N14)-SUM(W8:W10, W12:W13))*(1+$X$33)^(5.5), 0.05) -> #NUM!
S36: Total value of Others at 2030 = | W36: =MROUND(N15*(1.07)^(5.5), 0.05) -> 18
J76: SBG TopCo de-grossing post-Covid:
N78: FY19 | O78: FY20 | P78: FY21 | Q78: FY22 | R78: FY23
N79: Mar. '20 | O79: Mar. '21 | P79: Mar. '22 | Q79: Mar. '23 | R79: Mar. '24
J81: Gross debt $bn | N81: ='Net debt & LTV'!BJ79/1000 -> 59.990205 | O81: ='Net debt & LTV'!BK79/1000 -> 55.62596 | P81: ='Net debt & LTV'!BL79/1000 -> 60.807558 | Q81: ='Net debt & LTV'!BM79/1000 -> 47.229761 | R81: ='Net debt & LTV'!BN79/1000 -> 44.887431
J82: Cash $bn | N82: ='Net debt & LTV'!BJ171/1000 -> 13.373013 | O82: ='Net debt & LTV'!BK171/1000 -> 17.597119 | P82: ='Net debt & LTV'!BL171/1000 -> 20.447961 | Q82: ='Net debt & LTV'!BM171/1000 -> 25.870396 | R82: ='Net debt & LTV'!BN171/1000 -> 14.522614
J83: Net debt $bn | N83: ='Net debt & LTV'!BJ245/1000 -> 46.617192 | O83: ='Net debt & LTV'!BK245/1000 -> 38.028841 | P83: ='Net debt & LTV'!BL245/1000 -> 40.359596 | Q83: ='Net debt & LTV'!BM245/1000 -> 21.359365 | R83: ='Net debt & LTV'!BN245/1000 -> 30.364817
J85: LTV % | N85: ='Valuation & SBG NAV'!BY37 -> 0.14183835 | O85: ='Valuation & SBG NAV'!BZ37 -> 0.12203947 | P85: ='Valuation & SBG NAV'!CA37 -> 0.20362381 | Q85: ='Valuation & SBG NAV'!CB37 -> 0.11027095 | R85: ='Valuation & SBG NAV'!CC37 -> 0.08437706
J106: SBG TopCo de-grossing post-Covid:
J108: TopCo gross cash | M108: =MROUND('Net debt & LTV'!$AP$171/1000, 0.1) -> 14.5
I109: Add: | J109: DT exercise of T-Mobile call options | M109: =MROUND(((28.2*FP!$G$8)+(6.7*103))/1000, 0.1) -> 6.8
...

Sheet New SBG Valuation
A1: SoftBank Group Corp.
A2: year end March ¥m
B4: * Arm position net of $13.5bn margin loan. | E4: = need to update all-in values "today" every time before publication..!
B6: Company | C6: Public vs. private | D6: % stake | E6: All-in value today $bn | F6: P.F. value today $bn | G6: % SBG market cap. today | H6: Valuation methodology today | I6: All-in value 2030 $bn | J6: SBG value 2030 $bn | K6: 2030 valuation methodology | L6: delta vs. previous
B7: Arm* | C7: Public | D7: 0.9 | E7: 132 | F7: =D7*E7-20 -> 98.8 | G7: =F7/(FP!$D$13/1000) -> 0.66303947 | H7: 90% of Arm's $xxxbn market cap. less $13.5bn margin loan. | I7: =MROUND($E$7*(265/FP!$L$5), 5) -> 280 | J7: =D7*I7-25 -> 227 | K7: 38x EV/EBIT in Mar. '31E less ABF. | L7: =J7-'[63]New SBG Valuation'!J7 -> -11.5 | M7: = uses Arm Valuation tab Method 4: 38x peer group EV/EBIT multiple -> $265 per Arm share in Mar. '31E.
B8: Ampere Computing | C8: Private | D8: 1 | E8: 6.5 | F8: =D8*E8 -> 6.5 | G8: =F8/(FP!$D$13/1000) -> 0.043621017 | H8: All-in $6.5bn acquisition value. | I8: 27.5 | J8: =D8*I8 -> 27.5 | K8: 30x P/E in Mar. '31E on "in-house" CPU chip unit. | L8: =J8-'[63]New SBG Valuation'!J8 -> 0
B9: Graphcore | C9: Private | D9: 1 | E9: 0.65 | F9: =D9*E9 -> 0.65 | G9: =F9/(FP!$D$13/1000) -> 0.0043621017 | H9: Est. all-in acquisition value. | I9: ??? | J9: ??? | K9: Optionality on "in-house" accelerator.
B10: SoftBank "in-house" semis franchise (A) | F10: =SUM(F7:F9) -> 105.95 | G10: =F10/(FP!$D$13/1000) -> 0.71102258 | J10: =SUM(J7:J8) -> 254.5 | L10: =J10-'[63]New SBG Valuation'!J10 -> -11.5
B11: OpenAI | C11: Private | D11: 0.1325 | E11: 730 | F11: ='Valuation & SBG NAV'!$BU$57 -> 109.425 | G11: =F11/(FP!$D$13/1000) -> 0.73434305 | H11: $730bn pre-money CY26 valuation. | I11: =MROUND(17.5*200, 5) -> 3500 | J11: =D11*I11-13.25%*76-'OpenAI Valuation table'!$L$79+3*(1.03)^(5) -> 409.95442 | K11: 12.5x EV/Sales in FY30E less MgmtCo 17.25%. | L11: =J11-'[63]New SBG Valuation'!J11 -> 73.75442 | M11: = adjusted for 13% P.F. share of capital contributions to cover remaining $76bn of $218bn '26E-'30E cash burn not covered by CY25 ($41bn) or CY26 ($110bn) funding rounds; less MgmtCo 17.25% share.
B12: DigitalBridge | C12: Public | D12: 1 | E12: 2.9 | F12: =D12*E12 -> 2.9 | G12: =F12/(FP!$D$13/1000) -> 0.019461685 | H12: $16/share transaction value. | I12: =E12*(1.1)^(5) -> 4.670479 | J12: =D12*I12 -> 4.670479 | K12: 10% p.a. from $2.9bn transaction value. | L12: =J12-'[63]New SBG Valuation'!J12 -> 0
B13: Stargate | C13: Private | D13: 0.5 | E13: 1 | F13: =D13*E13 -> 0.5 | G13: =F13/(FP!$D$13/1000) -> 0.0033554629 | H13: $1bn SoftBank & OpenAI equity to SB Energy. | I13: =85%*20*2*2500*85%/1000 -> 72.25 | J13: =D13*I13-P14-U14-3*2 -> 27.619321 | K13: 20x EV/EBIT in FY30E less debt, preferreds, etc. | L13: =J13-'[63]New SBG Valuation'!J13 -> -3.8806786 | M13: = shifted from "neocloud" to "colocation" valuation approach -> assume OpenAI PBC buys and owns chips at SB Energy data centers.
B14: SoftBank "core" AI assets (B) | F14: =SUM(F11:F13) -> 112.825 | G14: =F14/(FP!$D$13/1000) -> 0.7571602 | J14: =SUM(J11:J13) -> 442.24422 | L14: =J14-'[63]New SBG Valuation'!J14 -> 69.873741 | M14: Ares $800m "preferreds" in '30E -> | P14: =MROUND(0.8*(1.1)^(5), 0.5) -> 1.5 | R14: OpenAI PBC minority equity in '30E -> | U14: =0.5*(1.15)^(5) -> 1.0056786 | W14: + 3 years of $2bn p.a. equity contribution by SoftBank TopCo.
B15: SoftBank core semis + AI gross asset value = (A+B) | F15: =F10+F14 -> 218.775 | G15: =F15/(FP!$D$13/1000) -> 1.4681828 | J15: =J10+J14 -> 696.74422 | L15: =J15-'[63]New SBG Valuation'!J15 -> 58.373741
B16: Less: TopCo net debt | F16: =-MROUND('Valuation & SBG NAV'!$BU$71, 0.5) -> -77 | G16: =F16/(FP!$D$13/1000) -> -0.51674128 | J16: =($F$16)*(1.04)^(5) -> -93.682273 | L16: =J16-'[63]New SBG Valuation'!J16 -> -6.9217889
B17: SoftBank core semis + AI equity value (C) | F17: =SUM(F15:F16) -> 141.775 | G17: =F17/(FP!$D$13/1000) -> 0.9514415 | J17: =SUM(J15:J16) -> 603.06195 | L17: =J17-'[63]New SBG Valuation'!J17 -> 51.451952
B18: ABB Robotics | C18: Private | D18: 0 | E18: 5.4 | F18: =D18*E18 -> 0 | G18: =F18/(FP!$D$13/1000) -> 0 | H18: SoftBank transaction value. | I18: =E18*(1.2)^(5) -> 13.436928 | J18: =I18 -> 13.436928 | K18: 20% p.a. from $5.4bn transaction value. | L18: =J18-'[63]New SBG Valuation'!J18 -> 0
B19: Symbotic | C19: Public | D19: 0.068 | E19: 32.5 | F19: =D19*E19 -> 2.21 | G19: =F19/(FP!$D$13/1000) -> 0.014831146 | H19: Market value. | I19: =MROUND((70/54.5)*E19, 0.25) -> 41.75 | J19: =D19*I19 -> 2.839 | K19: Arete DCF. | L19: =J19-'[63]New SBG Valuation'!J19 -> -0.017
B20: GreenBox JV | C20: Private | D20: 0.65 | E20: 0 | F20: =D20*E20 -> 0 | G20: =F20/(FP!$D$13/1000) -> 0 | H20: n/a | I20: =2300*100/35/1000 -> 6.5714286 | J20: =D20*I20 -> 4.2714286 | K20: Arete DCF. | L20: =J20-'[63]New SBG Valuation'!J20 -> 0
B21: AutoStore | C21: Public | D21: 0.4 | E21: 3.65 | F21: =D21*E21 -> 1.46 | G21: =F21/(FP!$D$13/1000) -> 0.0097979516 | H21: Market value. | I21: =MROUND((20.5/10.5)*E21, 0.25) -> 7.25 | J21: =D21*I21 -> 2.9 | K21: Arete DCF. | L21: =J21-'[63]New SBG Valuation'!J21 -> 0.2
B22: Nuro | C22: Private | D22: =F22/E22 -> 0.18333333 | E22: 6 | F22: =MROUND(54%*2.1, 0.1) -> 1.1 | G22: =F22/(FP!$D$13/1000) -> 0.0073820183 | H22: $6bn Series E funding round valuation. | I22: =E22*(1.25)^(5) -> 18.310547 | J22: =D22*I22 -> 3.3569336 | K22: 25% p.a. from $6bn Aug. '25 valuation. | L22: =J22-'[63]New SBG Valuation'!J22 -> 3.3569336
B23: Wayve | C23: Private | D23: =F23/E23 -> 0.15116279 | E23: 8.6 | F23: 1.3 | G23: =F23/(FP!$D$13/1000) -> 0.0087242035 | H23: Arete ests. | I23: =E23*(1.25)^(5) -> 26.245117 | J23: =D23*I23 -> 3.9672852 | K23: 25% p.a. from $8bn Oct. '25 valuation. | L23: =J23-'[63]New SBG Valuation'!J23 -> 0
B24: Skild AI | C24: Private | D24: =F24/E24 -> 0.12857143 | E24: 14 | F24: 1.8 | G24: =F24/(FP!$D$13/1000) -> 0.012079666 | H24: Arete ests. | I24: =E24*(1.125)^(5) -> 25.228455 | J24: =D24*I24 -> 3.2436584 | K24: 12.5% p.a. from $8bn Oct. '25 valuation.
B25: Boston Dynamics | C25: Private | D25: 0.125 | E25: 1.1 | F25: =D25*E25 -> 0.1375 | G25: =F25/(FP!$D$13/1000) -> 0.00092275229 | H25: Hyundai Motor Group Dec. '20 transaction value. | I25: =0.5*39 -> 19.5 | J25: =D25*I25 -> 2.4375 | K25: 50% discount on Figure AI $39bn mark. | L25: =J25-'[63]New SBG Valuation'!J24 -> 0
B26: Autonomous and Robotics (D) | F26: =SUM(F18:F25) -> 8.0075 | G26: =F26/(FP!$D$13/1000) -> 0.053737738 | J26: =SUM(J18:J25) -> 36.452734 | L26: =J26-'[63]New SBG Valuation'!J25 -> 6.783592
B27: NVIDIA | C27: Public | D27: ='SoftBank Other (13F)'!$AX$50 -> 0.0013214179 | E27: 4600 | F27: 0 | G27: 0 | H27: Market value. | I27: =MROUND(E27*(1.1)^(5), 5) -> 7410 | J27: 0 | K27: Fully exited. | L27: =J27-'[63]New SBG Valuation'!J26 -> 0
B28: Intel | C28: Public | D28: =F28/E28 -> 0.013391304 | E28: 225 | F28: =2*34.65/23 -> 3.0130435 | G28: =F28/(FP!$D$13/1000) -> 0.020220311 | H28: Market value. | I28: =MROUND(E28*(1.05)^(5), 5) -> 285 | J28: =D28*I28 -> 3.8165217 | K28: 5% p.a. growth. | L28: =J28-'[63]New SBG Valuation'!J27 -> -0.031461498
B29: TSMC | C29: Public | D29: n/m | E29: 1650 | F29: ='SoftBank Other (13F)'!$BA$8/1000 -> 0.743581 | G29: =F29/(FP!$D$13/1000) -> 0.0049901169 | H29: Market value. | I29: =MROUND(E29*(1.08)^(5), 5) -> 2425 | J29: =MROUND(F29*(1.08)^(5), 0.1) -> 1.1 | K29: 8% p.a. growth. | L29: =J29-'[63]New SBG Valuation'!J28 -> 0.4674202
B30: Oracle | C30: Public | D30: n/m | E30: 695 | F30: 0 | G30: 0 | H30: Market value. | I30: =E30 -> 695 | J30: =F30 -> 0 | K30: Fully exited. | L30: =J30-'[63]New SBG Valuation'!J29 -> 0
B31: Publicly-listed semis + AI stakes (E) | F31: =SUM(F27:F30) -> 3.7566245 | G31: =F31/(FP!$D$13/1000) -> 0.025210428 | J31: =SUM(J27:J30) -> 4.9165217 | L31: =J31-'[63]New SBG Valuation'!J30 -> 0.4359587
B32: ByteDance | C32: Private | D32: =MROUND(54%*3.25%, 0.05%) -> 0.0175 | E32: =MROUND('SVF1'!$AX$129/0.0325/1000, 5) -> 505 | F32: =D32*E32 -> 8.8375 | G32: =F32/(FP!$D$13/1000) -> 0.059307806 | H32: SVF1 mark which excl. TikTok U.S. value. | I32: =MROUND(8*50%*((95*1.08^(7))+(0.65*1.5*30)), 5) -> 770 | J32: =D32*I32 -> 13.475 | K32: 8x FY30E EBITDA on 50% EBITDA margin. | L32: =J32-'[63]New SBG Valuation'!J31 -> 0 | M32: = TikTok International revenue assumption based on 35% discount to Facebook/Instagram $30 ARPU and 1.5bn ex. China users.
B33: Revolut | C33: Private | D33: =F33/E33 -> 0.017923077 | E33: 65 | F33: ='SVF2'!$AX$147/1000 -> 1.165 | G33: =F33/(FP!$D$13/1000) -> 0.0078182285 | H33: FT reported $65bn funding round. | I33: =120*(1.1)^(5) -> 193.2612 | J33: =D33*I33 -> 3.4638354 | K33: Grey market IPO value (IG) + 10% p.a. | L33: =J33-'[63]New SBG Valuation'!J32 -> -1.9474782
B34: Perplexity | C34: Private | D34: =F34/E34 -> 0.0045282738 | E34: 20 | F34: =(20/18)*'SVF2'!$AX$146/1000 -> 0.090565476 | G34: =F34/(FP!$D$13/1000) -> 0.00060777819 | H34: $20bn funding round. | I34: =MROUND(0.5*E34*I11/E11, 5) -> 50 | J34: =I34*F34/E34 -> 0.22641369 | K34: Half value creation of OpenAI. | L34: =J34-'[63]New SBG Valuation'!J33 -> -0.090565476
B35: Other AI stakes (F) | F35: =SUM(F32:F34) -> 10.093065 | G35: =F35/(FP!$D$13/1000) -> 0.067733813 | J35: =SUM(J32:J34) -> 17.165249 | L35: =J35-'[63]New SBG Valuation'!J34 -> -2.0380437
B36: SoftBank Corp. (G) | C36: Public | D36: 0.4025 | E36: =F36/D36 -> 45.722225 | F36: ='Valuation & SBG NAV'!$BP$55 -> 18.403196 | G36: =F36/(FP!$D$13/1000) -> 0.12350248 | H36: Market value of 40% less $5bn+ K.K. margin loan. | I36: =MROUND(E36*(1.1)^(5), 5) -> 75 | J36: =D36*I36-7.75 -> 22.4375 | K36: 10% p.a. less K.K. ABF. | L36: =J36-'[63]New SBG Valuation'!J35 -> -6.775 | M36: = additional margin loan.
B37: Total SoftBank "core" equity (C+D+E+F) | F37: =F17+F26+F31+F35+F36 -> 182.03539 | G37: =F37/(FP!$D$13/1000) -> 1.221626 | J37: =J17+J26+J31+J35+J36 -> 684.03395 | L37: =J37-'[63]New SBG Valuation'!J36 -> 49.858459
B38: SoftBank "non-core"
B39: International telcos | F39: =SUM('P.F. NAV Table'!$E$16:$E$17) -> 5.8124681 | G39: =F39/(FP!$D$13/1000) -> 0.039007042 | H39: Market value net of ABF. | J39: 0 | L39: =J39-'[63]New SBG Valuation'!J38 -> -13.679841
B40: Publicly-listed SVF assets | F40: ='Alt. SoftBank Valuation'!$H$11 -> 13.505 | G40: =F40/(FP!$D$13/1000) -> 0.090631052 | H40: Market value. | J40: =F40*(1.125)^(5) -> 24.336449 | L40: =J40-'[63]New SBG Valuation'!J39 -> 3.3690822 | M40: = upgrade est. returns on lower Coupang starting price.
B41: Privately held SVF assets** | F41: ='Alt. SoftBank Valuation'!$H$21-SUM(F22:F23) -> 16.92417 | G41: =F41/(FP!$D$13/1000) -> 0.11357685 | H41: Private marks. | J41: =F41*(1.1)^(5) -> 27.256546 | L41: =J41-'[63]New SBG Valuation'!J40 -> -21.500723 | M41: = faster pace of PayPay monetisation to fund OpenAI PBC transaction.
B42: Other non-core publicly listed stakes | F42: ='Alt. SoftBank Valuation'!$H$12 -> 2.2121829 | G42: =F42/(FP!$D$13/1000) -> 0.014845795 | H42: Market value. | J42: =F42*(1.05)^(5) -> 2.8233683 | L42: =J42-'[63]New SBG Valuation'!J41 -> 0.061547392
...

Sheet Alt. SoftBank Valuation
A1: SoftBank Group Corp.
A2: year end March ¥m
B4: SoftBank March '26 valuation -> | H4: = must update formula at each note/publication.
G5: $m | H5: $bn
B6: SoftBank market cap. | G6: =MROUND(FP!$D$5*'Valuation & SBG NAV'!$BP$39/FP!$G$4, 5) -> 149010 | H6: =G6/1000 -> 149.01
B7: Less: International telcos net of ABF | G7: =MROUND(1000*H7, 5) -> 0 | H7: ='Valuation & SBG NAV'!$BU$62+'Valuation & SBG NAV'!$BU$63 -> 0
B8: SVF1 = 55% | G8: =MROUND('SVF1'!$AZ$39*'SVF1'!$AZ$74, 5) -> 7975 | H8: =G8/1000 -> 7.975
B9: SVF2 = 100% | G9: ='SVF2'!$AZ$68 -> 4505 | H9: =G9/1000 -> 4.505
B10: LatAm = 100% | G10: ='LatAm Funds'!$AZ$7 -> 1025 | H10: =G10/1000 -> 1.025
B11: Less: publicly listed SVF stakes | G11: =SUM(G8:G10) -> 13505 | H11: =SUM(H8:H10) -> 13.505
B12: Less: other publicly listed stakes | G12: =SUM('SoftBank Other (13F)'!BA10:BA15) -> 2212.1829 | H12: =G12/1000 -> 2.2121829
B13: Less: SVF privately held at $50c on the $1 | G13: =MROUND(G21*50%, 5) -> 9665 | H13: =G13/1000 -> 9.665
B14: SoftBank net market cap. | G14: =G6-G7-SUM(G11:G13) -> 123627.82 | H14: =H6-H7-SUM(H11:H13) -> 123.62782
B15: Add: TopCo net debt | G15: =MROUND(1000*H15, 5) -> 77000 | H15: =MROUND('Valuation & SBG NAV'!$BU$71, 0.5) -> 77
B16: SoftBank net enterprise value | G16: =SUM(G14:G15) -> 200627.82 | H16: =SUM(H14:H15) -> 200.62782 | I16: =100*H16/F52 -> 85.186965
B17: Enterprise value with SVF private fully-valued | G17: =G16-G13 -> 190962.82 | H17: =H16-H13 -> 190.96282 | I17: =100*H17/F52 -> 81.083187
G19: $m | H19: $bn
B20: Total SVF excl. OpenAI, ByteDance and Revolut | G20: =MROUND(1000*H20, 5) -> 32830 | H20: ='Valuation & SBG NAV'!$BU$61-'Valuation & SBG NAV'!$BU$57-(('SVF1'!$AZ$39*'SVF1'!$AZ$129+'SVF2'!$AZ$147)/1000) -> 32.82917
B21: Privately held assets by Vision Funds | G21: =G20-G11 -> 19325 | H21: =H20-H11 -> 19.32417
G23: $m | H23: $bn
B24: NVIDIA | G24: ='SoftBank Other (13F)'!BA6 -> 0 | H24: =G24/1000 -> 0
B25: TSMC | G25: ='SoftBank Other (13F)'!BA8 -> 743.581 | H25: =G25/1000 -> 0.743581
B26: Oracle | G26: ='SoftBank Other (13F)'!BA9 -> 0 | H26: =G26/1000 -> 0
B27: Total large cap. AI stocks | G27: =SUM(G24:G26) -> 743.581 | H27: =SUM(H24:H26) -> 0.743581
B29: * Arm position net of $13.5bn margin loan.
B30: Company | C30: Public vs. private | D30: % stake | E30: All-in value $bn | F30: SBG value $bn | G30: % SBG market cap. today | H30: Valuation methodology today
B31: Arm* | C31: Public | D31: 0.9 | E31: 162 | F31: =D31*E31-8.5 -> 137.3 | G31: =F31/$H$6 -> 0.92141467 | H31: SoftBank's 90% share of Arm's $162bn market cap. less $13.5bn margin loan.
B32: Ampere Computing | C32: Private | D32: 1 | E32: 6.5 | F32: =D32*E32 -> 6.5 | G32: =F32/$H$6 -> 0.043621233 | H32: All-in SoftBank acquisition value.
B33: Graphcore | C33: Private | D33: 1 | E33: 0.65 | F33: =D33*E33 -> 0.65 | G33: =F33/$H$6 -> 0.0043621233 | H33: Est. all-in SoftBank acquisition value.
B34: SoftBank "in-house" semis franchise | F34: =SUM(F31:F33) -> 144.45 | G34: =F34/$H$6 -> 0.96939803
B35: OpenAI | C35: Private | D35: ='SoftBank Other (13F)'!$BA$31/1000/FP!$Q$11 -> 0.1088 | E35: =FP!$Q$11 -> 500 | F35: =D35*E35 -> 54.4 | G35: =F35/$H$6 -> 0.36507617 | H35: $500bn Sep. '25 employee share sale valuation.
B36: SoftBank Corp. | C36: Public | D36: 0.4025 | E36: 71.25 | F36: ='Valuation & SBG NAV'!$BP$55 -> 18.403196 | G36: =F36/$H$6 -> 0.12350309 | H36: Market value of 40.25% less $5bn+ K.K. margin loan.
B37: Stargate | C37: Private | D37: 0.5 | E37: 0 | F37: =D37*E37 -> 0 | G37: =F37/$H$6 -> 0 | H37: n/a
B38: NVIDIA | C38: Public | D38: ='SoftBank Other (13F)'!$AX$50 -> 0.0013214179 | E38: =MROUND(F38/D38, 5) -> 0 | F38: ='SoftBank Other (13F)'!$BA$6/1000 -> 0 | G38: =F38/$H$6 -> 0 | H38: Market value.
B39: Intel | C39: Public | D39: =F39/E39 -> 0.018629929 | E39: 172 | F39: =2*36.85/23 -> 3.2043478 | G39: =F39/$H$6 -> 0.021504247 | H39: Market value.
B40: TSMC | C40: Public | D40: n/m | E40: 1000 | F40: ='SoftBank Other (13F)'!$BA$8/1000 -> 0.743581 | G40: =F40/$H$6 -> 0.0049901416 | H40: Market value.
B41: Oracle | C41: Public | D41: n/m | E41: 705 | F41: ='SoftBank Other (13F)'!$BA$9/1000 -> 0 | G41: =F41/$H$6 -> 0 | H41: Market value.
B42: "Other" semis holdings | F42: =SUM(F38:F41) -> 3.9479288
B43: ByteDance | C43: Private | D43: =MROUND(54%*3.25%, 0.05%) -> 0.0175 | E43: =MROUND('SVF1'!$AX$129/0.0325/1000, 5) -> 505 | F43: =D43*E43 -> 8.8375 | G43: =F43/$H$6 -> 0.0593081 | H43: SVF1 private mark which excludes potential TikTok US value.
B44: Symbotic | C44: Public | D44: 0.068 | E44: 37.25 | F44: =D44*E44 -> 2.533 | G44: =F44/$H$6 -> 0.016998859 | H44: Market value.
...

Sheet Valuation table summary
A1: SoftBank Group Corp.
A2: year end March ¥m
D3: = excludes variable Prepaid forward contracts where both asset and liability move in tandem i.e., "net" equity remains fixed.
C4: A | D4: B | E4: A + B = C | F4: D | H4: E = C x (1 - D) | I4: F = E - B
C5: SBG reported NAV $bn | D5: Asset-backed financing $bn | E5: Gross exposure $bn | F5: Arete % gross discount | G5: Comments | H5: Arete Gross exposure $bn | I5: Arete est. NAV $bn
B6: Alibaba | C6: ='Valuation & SBG NAV'!BP54 -> 0 | E6: ='Valuation & SBG NAV'!BP149 -> 0 | F6: ='Valuation & SBG NAV'!C175 -> 0 | G6: ='Valuation & SBG NAV'!D175 -> = minimal exposure (due to variable prepaid forward contracts) and subject to near-term monetisation. | H6: ='Valuation & SBG NAV'!BP194 -> 0 | I6: ='Valuation & SBG NAV'!BP239 -> 0 | K6: SBG-reported NAV $bn | N6: =$C$21 -> 212.48849 | S6: SBG gross exposure $bn | V6: =$N$9 -> 296.46022
B7: SoftBank Corp. | C7: ='Valuation & SBG NAV'!BP55 -> 18.403196 | D7: ='Valuation & SBG NAV'!BP97 -> 7.7111541 | E7: ='Valuation & SBG NAV'!BP150 -> 26.11435 | F7: ='Valuation & SBG NAV'!C176 -> 0.15 | G7: ='Valuation & SBG NAV'!D176 -> = seen as SBG's core telcos asset i.e., no further monetisation of 40.5% holding. | H7: ='Valuation & SBG NAV'!BP195 -> 22.197197 | I7: ='Valuation & SBG NAV'!BP240 -> 14.486043 | K7: TopCo net debt $bn | N7: =$C$20 -> 51.124113 | S7: Arete discount $bn | V7: =-($E$18-$H$18) -> -33.052159
B8: SVF1 | C8: ='Valuation & SBG NAV'!BP56 -> 23.15 | E8: ='Valuation & SBG NAV'!BP151 -> 23.15 | F8: =1-MROUND(H8/E8, 5%) -> 0 | H8: ='Valuation & SBG NAV'!BP196 -> 23.414681 | I8: ='Valuation & SBG NAV'!BP241 -> 23.414681 | K8: ABF $bn | N8: =$D$18 -> 32.847618 | S8: Arete gross exposure $bn | V8: =SUM(V6:V7) -> 263.40807
B9: OpenAI | C9: ='Valuation & SBG NAV'!BP57 -> 54.4 | E9: ='Valuation & SBG NAV'!BP152 -> 54.4 | F9: =1-MROUND(H9/E9, 5%) -> 0 | H9: ='Valuation & SBG NAV'!BP197 -> 54.4 | I9: ='Valuation & SBG NAV'!BP242 -> 54.4 | K9: SBG gross exposure $bn | N9: =SUM(N6:N8) -> 296.46022 | S9: ABF $bn | V9: =-$N$8 -> -32.847618
B10: SVF2 excl. OpenAI | C10: ='Valuation & SBG NAV'!BP58 -> 28.99 | D10: ='Valuation & SBG NAV'!BP100 -> 5.33 | E10: ='Valuation & SBG NAV'!BP153 -> 34.32 | F10: =1-MROUND(H10/E10, 5%) -> 0.6 | H10: ='Valuation & SBG NAV'!BP198 -> 14.15128 | I10: ='Valuation & SBG NAV'!BP243 -> 8.82128 | S10: TopCo net debt $bn | V10: =-$N$7 -> -51.124113
B11: SVF2 | C11: ='Valuation & SBG NAV'!BP59 -> 83.39 | D11: ='Valuation & SBG NAV'!BP101 -> 5.33 | E11: ='Valuation & SBG NAV'!BP154 -> 88.72 | F11: =1-MROUND(H11/E11, 5%) -> 0.25 | H11: ='Valuation & SBG NAV'!BP199 -> 68.55128 | I11: ='Valuation & SBG NAV'!BP244 -> 63.22128 | S11: Arete est. NAV $bn | V11: =SUM(V8:V10) -> 179.43633
B12: LatAm Funds | C12: ='Valuation & SBG NAV'!BP60 -> 6.773 | E12: ='Valuation & SBG NAV'!BP155 -> 6.773 | F12: =1-MROUND(H12/E12, 5%) -> 0.5 | H12: ='Valuation & SBG NAV'!BP200 -> 3.3865 | I12: ='Valuation & SBG NAV'!BP245 -> 3.3865
B13: SBG's equity in Vision Funds | C13: ='Valuation & SBG NAV'!BP61 -> 113.313 | D13: ='Valuation & SBG NAV'!BP103 -> 5.33 | E13: ='Valuation & SBG NAV'!BP156 -> 118.643 | F13: =1-MROUND(H13/E13, 5%) -> 0.2 | H13: ='Valuation & SBG NAV'!BP201 -> 95.352461 | I13: ='Valuation & SBG NAV'!BP246 -> 90.022461
B14: T-Mobile US | C14: ='Valuation & SBG NAV'!BP62 -> 3.45776 | D14: ='Valuation & SBG NAV'!BP104 -> 0 | E14: ='Valuation & SBG NAV'!BP157 -> 3.45776 | F14: ='Valuation & SBG NAV'!C183 -> 0 | G14: ='Valuation & SBG NAV'!D183 -> = Arete have xx% upside on T-Mobile US and non-core + easily monetisable e.g., buyback participation. | H14: ='Valuation & SBG NAV'!BP202 -> 3.45776 | I14: ='Valuation & SBG NAV'!BP247 -> 3.45776
B15: Deutsche Telekom | C15: ='Valuation & SBG NAV'!BP63 -> 0 | D15: ='Valuation & SBG NAV'!BP105 -> 0 | E15: ='Valuation & SBG NAV'!BP158 -> 0 | F15: ='Valuation & SBG NAV'!C184 -> 0 | G15: ='Valuation & SBG NAV'!D184 -> = Arete have xx% upside on DT and non-core + easily monetisable e.g., buyback participation. | H15: ='Valuation & SBG NAV'!BP203 -> 0 | I15: ='Valuation & SBG NAV'!BP248 -> 0
B16: Arm | C16: ='Valuation & SBG NAV'!BP64 -> 97.598771 | D16: ='Valuation & SBG NAV'!BP106 -> 19.806464 | E16: ='Valuation & SBG NAV'!BP159 -> 117.40524 | F16: ='Valuation & SBG NAV'!C185 -> 0.1 | G16: = uses Arete FYXX $xx target price for 90% Arm gross exposure and applies 10% holding discount. | H16: ='Valuation & SBG NAV'!BP204 -> 117.24476 | I16: ='Valuation & SBG NAV'!BP249 -> 97.438291
B17: Others (incl. OpenAI + Stargate + Ampere + Graphcore) | C17: ='Valuation & SBG NAV'!BP65 -> 30.839879 | E17: ='Valuation & SBG NAV'!BP160 -> 30.839879 | F17: =1-MROUND(H17/E17, 5%) -> 0.2 | G17: ='Valuation & SBG NAV'!D188 -> = 15% discount for other assets (e.g., NVIDIA, TSMC, Oracle equity stakes). | H17: ='Valuation & SBG NAV'!BP205 -> 25.155891 | I17: ='Valuation & SBG NAV'!BP250 -> 25.155891
B18: Total | C18: ='Valuation & SBG NAV'!BP66 -> 263.61261 | D18: ='Valuation & SBG NAV'!BP108 -> 32.847618 | E18: ='Valuation & SBG NAV'!BP161 -> 296.46022 | F18: =1-MROUND(H18/E18, 5%) -> 0.1 | H18: ='Valuation & SBG NAV'!BP206 -> 263.40807 | I18: ='Valuation & SBG NAV'!BP251 -> 230.56045
B20: Less: TopCo standalone net interest-bearing debt | C20: ='Valuation & SBG NAV'!BP71 -> 51.124113 | I20: =C20 -> 51.124113
B21: SBG NAV $bn | C21: =C18-C20 -> 212.48849 | F21: =1-MROUND(I21/C21, 2.5%) -> 0.15 | I21: =I18-I20 -> 179.43633
B22: FX | C22: =FP!$G$4 -> 155.1 | I22: =FP!$G$4 -> 155.1
B23: SBG NAV ¥tn | C23: =C21*C22/1000 -> 32.956965 | I23: =I21*I22/1000 -> 27.830575
B24: Outstanding shares (millions) | I24: ='Valuation & SBG NAV'!$BO$39 -> 1427.962
B25: Target price ¥ | I25: =MROUND(1000000*I23/I24, 100) -> 19500
B26: % upside/(downside) | I26: =I25/FP!$D$5-1 -> 0.20481928
C28: A | D28: B | E28: A + B = C | F28: D | H28: E = C x (1 - D) | I28: F = E - B
B29: SoftBank Vision Funds | C29: SBG reported NAV $bn | D29: Asset-backed financing $bn | E29: Gross exposure $bn | F29: Arete % gross discount | G29: Comments | H29: Arete Gross exposure $bn | I29: Arete est. NAV $bn
B30: SVF1 Publicly listed | C30: =E30 -> 10.701359 | E30: ='Valuation & SBG NAV'!BK216 -> 10.701359 | F30: ='Valuation & SBG NAV'!C177 -> 0 | G30: ='Valuation & SBG NAV'!D177 -> = to be monetised in near future & already marked-to-market by SBG. | H30: =E30*(1-F30) -> 10.701359
B31: SVF1 Privately held ex. ByteDance | C31: =E31 -> 6.2863331 | E31: ='Valuation & SBG NAV'!BK217 -> 6.2863331 | F31: ='Valuation & SBG NAV'!C178 -> 0.25 | G31: ='Valuation & SBG NAV'!D178 -> = highly skeptical of under the bonnet SVF valuations given investment track record. | H31: =E31*(1-F31) -> 4.7147498
B32: ByteDance | C32: =E32 -> 7.6244 | E32: ='Valuation & SBG NAV'!BK218 -> 7.6244 | F32: ='Valuation & SBG NAV'!C179 -> 0 | G32: ='Valuation & SBG NAV'!D179 -> = value separately: think SBG carrying value conservative and already marked down 20% for potential US ban. | H32: =E32*(1-F32) -> 7.6244
B33: SVF1 | C33: =C8 -> 23.15 | E33: =E8 -> 23.15 | F33: =1-MROUND(H33/E33, 5%) -> 0 | H33: =H8 -> 23.414681 | I33: =I8 -> 23.414681
B34: SVF2 Publicly listed | C34: ='SVF2'!$AR$4*'Valuation table summary'!$C$11 -> 8.6989568 | E34: ='Valuation & SBG NAV'!BK229 -> 3.6361146 | F34: ='Valuation & SBG NAV'!C180 -> 0.15 | G34: ='Valuation & SBG NAV'!D180 -> = monetisation timeline less obvious albeit marked-to-market by SBG. | H34: =E34*(1-F34) -> 3.0906974
B35: SVF2 Privately held | C35: =C36-C34 -> 74.691043 | E35: ='Valuation & SBG NAV'!BK230 -> 28.325339 | F35: ='Valuation & SBG NAV'!C181 -> 0.67 | G35: ='Valuation & SBG NAV'!D181 -> = see SVF1 explanation: additional discount due to peak tech valuation "vintage". | H35: =E35*(1-F35) -> 9.347362
B36: SVF2 | C36: =C11 -> 83.39 | D36: =D11 -> 5.33 | E36: =E11 -> 88.72 | F36: =1-MROUND(H36/E36, 5%) -> 0.25 | H36: =H11 -> 68.55128 | I36: =I11 -> 63.22128
B37: LatAm Funds | C37: =C12 -> 6.773 | D37: =D12 -> 0 | E37: =E12 -> 6.773 | F37: =1-MROUND(H37/E37, 5%) -> 0.5 | G37: ='Valuation & SBG NAV'!D182 -> = poor visibility on investments plus significant EM risk etc etc. | H37: =H12 -> 3.3865 | I37: =I12 -> 3.3865
B39: Check
B40: Alibaba | E40: =E6-(C6+D6) -> 0 | H40: =H6-(E6*(1-F6)) -> 0
B41: SoftBank Corp. | E41: =E7-(C7+D7) -> 0 | H41: =H7-(E7*(1-F7)) -> 0
B42: SVF1 | E42: =E8-(C8+D8) -> 0
B43: SVF2 | E43: =E11-(C11+D11) -> 0
...

Sheet FP
A1: SoftBank Group Corp.
A2: year end March ¥m
N3: = 10-for-1 stock split to SoftBank KK shares executed on 30th September -> need to adjust model. | Z3: = update from T-Mobile US and DT models.
F4: JPY/USD | G4: 155.1 | I4: Prior Q Arm share price $ | L4: 109.31 | N4: Prior Q SoftBank Corp. share price ¥ | Q4: =10*214.8 -> 2148 | S4: SoftBank Corp. % ownership | V4: 0.4025 | X4: SoftBank Corp. net debt ¥bn | Z4: ='Financial statements KK'!$AK$292 -> 3731.1 | AB4: SoftBank Corp. net debt $bn | AE4: =MROUND(Z4/$G$4, 0.05) -> 24.05
B5: Share price ¥ | D5: =MROUND(D9*4, 5) -> 16185 | F5: JPY/EUR | G5: 183.25 | I5: Arm share price $ | L5: 124.37 | N5: SoftBank Corp. share price ¥ | Q5: =10*212.7 -> 2127 | X5: SoftBank Corp. towers liabs. ¥bn | Z5: ='Financial statements KK'!$AK$252 -> 490.9 | AB5: SoftBank Corp. towers liabs. $bn | AE5: =MROUND(Z5/$G$4, 0.05) -> 3.15
B6: Shares outstanding (m) | D6: 1427.962 | F6: JPY/GBP | G6: 209.15 | I6: Arm shares outstanding (m) | L6: ='[64]P&L'!$FO$69 -> 1048.8885 | N6: SoftBank Corp. shares outstanding (m) | Q6: ='Financial statements KK'!$AL$58 -> 4731.0511 | S6: SoftBank Corp. stake. ¥bn | X6: T-Mobile US net debt $bn | Z6: 74.65 | AB6: T-Mobile US net debt $bn | AE6: =MROUND(Z6, 0.05) -> 74.65
B7: Market cap. ¥bn | D7: =D5*D6/1000 -> 23111.565 | I7: Arm market cap. $bn | L7: =L5*L6/1000 -> 130.45026 | N7: SoftBank Corp. market cap. ¥bn | Q7: =Q5*Q6/1000 -> 10062.946 | X7: DT net debt €m | Z7: 93.746 | AB7: DT net debt $bn | AE7: =MROUND(Z7*$G$5/$G$4, 0.05) -> 110.75
F8: T-Mobile US $ | G8: 216.11 | S8: SoftBank Corp. stake. $m | X8: = T-Mobile/DT taken from reports or Arete model.
B9: Share price ¥ | D9: 4046 | F9: DT € | G9: 33.21 | I9: Arm target price $ FY27E | L9: 138 | N9: Market cap. $m | Q9: =1000*Q7/$G$4 -> 64880.372
B10: Shares outstanding (m) | D10: =4*D6 -> 5711.8481 | I10: Arm target price $ = discounted. | L10: =L9/1.075 -> 128.37209
B11: Market cap. ¥bn | D11: =D9*D10/1000 -> 23110.137 | F11: Thomson | G11: 20500 | I11: Arm target market cap. $bn | L11: =L9*L6/1000 -> 144.74661 | N11: OpenAI all-in valuation $bn | Q11: 500 | S11: OpenAI "discount" carried by SVF2 | V11: 0.05
F12: Reuters VC | N12: #2 Dec. '25 investment tranche SBG $bn | Q12: 22.5 | S12: OpenAI all-in valuation within SVF2 $bn | V12: =Q11*(1-V11) -> 475
B13: Market cap. $m | D13: =1000*D7/$G$4 -> 149010.74 | I13: Arm % ownership | L13: 0.9 | N13: #2 Dec. '25 syndicate $bn | Q13: 7.5
B14: vs. PF SBG reported NAV $m | D14: =1000*'Valuation table summary'!$C$21 -> 212488.49 | N14: Total #2 syndicate $bn | Q14: =SUM(Q12:Q13) -> 30 | T14: $35bn F-O
B15: % discount/(premium) | D15: =1-D13/D14 -> 0.29873502 | Q15: Tranche 1 = $15bn Amazon + $10bn SoftBank + $10bn NVIDIA but excludes $10bn Middle East & Venture Capital.
N16: OpenAI CY26 funding round assumptions -> | Q16: =(110-35)/(Q17+110-35) -> 0.093167702 | R16: =(110-35)/(R17+110-35) -> 0.093167702 | S16: =(110-35)/(S17+110-35) -> 0.093167702 | T16: =(110)/(T17+110) -> 0.13095238 | U16: = total dilution to existing OpenAI shareholders incl. full Amazon $50bn investment.
B17: March '31E target price | D17: ='New SBG Valuation'!$J$48 -> 18250 | N17: Pre-money valuation $bn | Q17: 730 | R17: 730 | S17: 730 | T17: 730
B18: Arete target market cap. $bn | D18: ='New SBG Valuation'!$J$47 -> 673.48018 | N18: + Funding round amount $bn | Q18: =10+10+15 -> 35 | R18: =10+10 -> 20 | S18: =10+10 -> 20 | T18: 35 | U18: -> assumptions = Amazon $15bn (+$35bn "when certain conditions are met"), NVIDIA $30bn, SoftBank Group $30bn, Middle East + VCs $10bn.
B19: % upside/(downside) | D19: =D17/D9-1 -> 3.5106278 | N19: Post-money valuation $bn | Q19: =SUM(Q17:Q18) -> 765 | R19: =Q19+R18 -> 785 | S19: =R19+S18 -> 805 | T19: =S19+T18 -> 840 | U19: https://www.theinformation.com/articles/openai-finalizing-first-commitments-100-billion-mega-round?rc=oyp3ga
N20: % SVF2 stake in OpenAI pre-funding round | Q20: 0.115 | R20: Tranche #2 | S20: Tranche #3
B21: = using OLD share count (pre- 4-for-1 share split on 31 Dec. '25). | G21: = using NEW share count (pre- 4-for-1 share split on 31 Dec. '25). | N21: SVF2 tranche #1 $bn | Q21: 10 | R21: 10 | S21: 10 | U21: = we assume two additional $10bn tranches by SoftBank of which 25% syndicated.
C22: NAV/share ¥ | D22: % discount to NAV | E22: % LTV | H22: NAV/share ¥ | I22: % discount to NAV | J22: % LTV
B23: F1Q23 | C23: ='Valuation & SBG NAV'!$BB$41 -> 10610 | D23: ='SVF Indexes'!I28 -> 0.36270096 | E23: ='Valuation & SBG NAV'!$BB$37 -> 0.079881657 | G23: F1Q23 | H23: =C23/4 -> 2652.5 | I23: =D23 -> 0.36270096 | J23: =E23 -> 0.079881657
B24: F2Q23 | C24: ='Valuation & SBG NAV'!$BC$41 -> 11190 | D24: ='SVF Indexes'!I29 -> 0.43479586 | E24: ='Valuation & SBG NAV'!$BC$37 -> 0.10620915 | G24: F2Q23 | H24: =C24/4 -> 2797.5 | I24: =D24 -> 0.43479586 | J24: =E24 -> 0.10620915
B25: F3Q23 | C25: ='Valuation & SBG NAV'!$BD$41 -> 13120 | D25: ='SVF Indexes'!I30 -> 0.52053015 | E25: ='Valuation & SBG NAV'!$BD$37 -> 0.11418048 | G25: F3Q23 | H25: =C25/4 -> 3280 | I25: =D25 -> 0.52053015 | J25: =E25 -> 0.11418048
B26: F4Q23 | C26: ='Valuation & SBG NAV'!$BE$41 -> 18950 | D26: ='SVF Indexes'!I31 -> 0.52717783 | E26: ='Valuation & SBG NAV'!$BE$37 -> 0.08437706 | G26: F4Q23 | H26: =C26/4 -> 4737.5 | I26: =D26 -> 0.52717783 | J26: =E26 -> 0.08437706
B27: F1Q24 | C27: ='Valuation & SBG NAV'!$BG$41 -> 24060 | D27: ='SVF Indexes'!I32 -> 0.56691239 | E27: ='Valuation & SBG NAV'!$BG$37 -> 0.078149503 | G27: F1Q24 | H27: =C27/4 -> 6015 | I27: =D27 -> 0.56691239 | J27: =E27 -> 0.078149503
B28: F2Q24 | C28: ='Valuation & SBG NAV'!$BH$41 -> 20050 | D28: ='SVF Indexes'!I33 -> 0.57876594 | E28: ='Valuation & SBG NAV'!$BH$37 -> 0.12462281 | G28: F2Q24 | H28: =C28/4 -> 5012.5 | I28: =D28 -> 0.57876594 | J28: =E28 -> 0.12462281
B29: F3Q24 | C29: ='Valuation & SBG NAV'!$BI$41 -> 20360 | D29: ='SVF Indexes'!I34 -> 0.54856851 | E29: ='Valuation & SBG NAV'!$BI$37 -> 0.12860113 | G29: F3Q24 | H29: =C29/4 -> 5090 | I29: =D29 -> 0.54856851 | J29: =E29 -> 0.12860113
B30: F4Q24 | C30: ='Valuation & SBG NAV'!$BJ$41 -> 17880 | D30: ='SVF Indexes'!I35 -> 0.58093385 | E30: ='Valuation & SBG NAV'!$BJ$37 -> 0.18074594 | G30: F4Q24 | H30: =C30/4 -> 4470 | I30: =D30 -> 0.58093385 | J30: =E30 -> 0.18074594
B31: F1Q25 | C31: ='Valuation & SBG NAV'!$BL$41 -> 22750 | D31: ='SVF Indexes'!I36 -> 0.5367284 | E31: ='Valuation & SBG NAV'!$BL$37 -> 0.17008197 | G31: F1Q25 | H31: =C31/4 -> 5687.5 | I31: =D31 -> 0.5367284 | J31: =E31 -> 0.17008197
B32: F2Q25 | C32: ='Valuation & SBG NAV'!$BM$41 -> 23380 | D32: ='SVF Indexes'!I37 -> 0.20075075 | E32: ='Valuation & SBG NAV'!$BM$37 -> 0.16457602 | G32: F2Q25 | H32: =C32/4 -> 5845 | I32: =D32 -> 0.20075075 | J32: =E32 -> 0.16457602
B33: F3Q25 | C33: ='Valuation & SBG NAV'!$BN$41 -> 21670 | D33: ='Valuation & SBG NAV'!$BN$42 -> 0.25311491 | E33: ='Valuation & SBG NAV'!$BN$37 -> 0.20625962 | G33: F3Q25 | H33: ='Valuation & SBG NAV'!$BN$46 -> 5420 | I33: ='Valuation & SBG NAV'!$BN$47 -> 0.25350554 | J33: ='Valuation & SBG NAV'!$BN$37 -> 0.20625962
B34: F4Q25E | C34: ='Valuation & SBG NAV'!$BO$41 -> 23080 | D34: ='Valuation & SBG NAV'!$BO$42 -> 0.2987435 | E34: ='Valuation & SBG NAV'!$BO$37 -> 0.19393653 | G34: F4Q25E | H34: ='Valuation & SBG NAV'!$BO$46 -> 5770 | I34: ='Valuation & SBG NAV'!$BO$47 -> 0.29878683 | J34: ='Valuation & SBG NAV'!$BO$37 -> 0.19393653
G35: F1Q26E | H35: ='Valuation & SBG NAV'!$BQ$46 -> 6290 | I35: ='Valuation & SBG NAV'!$BQ$47 -> 0.35675676 | J35: ='Valuation & SBG NAV'!$BQ$37 -> 0.19402876
G36: F2Q26E | H36: ='Valuation & SBG NAV'!$BR$46 -> 6280 | I36: ='Valuation & SBG NAV'!$BR$47 -> 0.35573248 | J36: ='Valuation & SBG NAV'!$BR$37 -> 0.22402141
G37: F3Q26E | H37: ='Valuation & SBG NAV'!$BS$46 -> 6220 | I37: ='Valuation & SBG NAV'!$BS$47 -> 0.34951768 | J37: ='Valuation & SBG NAV'!$BS$37 -> 0.25264093
G38: F4Q26E | H38: ='Valuation & SBG NAV'!$BT$46 -> 6130 | I38: ='Valuation & SBG NAV'!$BT$47 -> 0.33996737 | J38: ='Valuation & SBG NAV'!$BT$37 -> 0.25267031

Sheet P.F. NAV Table
A1: SoftBank Group Corp.
A2: year end March ¥tn | I2: Annual
A4: Net asset value & LTV ¥tn = as reported by SBG.
B5: = update quarterly figures by adjusting column refs from Valuation & SBG NAV and delta columns update automatically.
B6: F2Q25E | D6: Pro Forma | F6: delta
B7: ¥tn | C7: $bn | D7: ¥tn | E7: $bn | F7: ¥tn | G7: $bn | I7: = impact on SoftBank NAV per share.
A8: Alibaba | B8: ='Quarterly NAV Table'!D8 -> 0 | C8: ='Quarterly NAV Table'!E8 -> 0 | D8: ='Valuation & SBG NAV'!BN10 -> 0 | E8: ='Valuation & SBG NAV'!BN54 -> 0 | F8: =D8-B8 -> 0 | G8: =E8-C8 -> 0 | I8: =1000000*F8/FP!$D$6 -> 0
A9: SoftBank Corp. | B9: ='Quarterly NAV Table'!D9 -> 2.92 | C9: ='Quarterly NAV Table'!E9 -> 18.650996 | D9: ='Valuation & SBG NAV'!BN11 -> 2.92 | E9: ='Valuation & SBG NAV'!BN55 -> 18.650996 | F9: =D9-B9 -> 0 | G9: =E9-C9 -> 0 | I9: =1000000*F9/FP!$D$6 -> 0
A10: SVF1 | B10: ='Quarterly NAV Table'!D10 -> 3.79 | C10: ='Quarterly NAV Table'!E10 -> 24.207971 | D10: ='Valuation & SBG NAV'!BN12 -> 3.79 | E10: ='Valuation & SBG NAV'!BN56 -> 24.207971 | F10: =D10-B10 -> 0 | G10: =E10-C10 -> 0 | I10: =1000000*F10/FP!$D$6 -> 0
A11: OpenAI | B11: ='Quarterly NAV Table'!D11 -> 8.516864 | C11: ='Quarterly NAV Table'!E11 -> 54.4 | D11: ='Valuation & SBG NAV'!BN13 -> 8.516864 | E11: ='Valuation & SBG NAV'!BN57 -> 54.4 | F11: =D11-B11 -> 0 | G11: =E11-C11 -> 0 | I11: =1000000*F11/FP!$D$6 -> 0
A12: SVF2 excl. OpenAI | B12: ='Quarterly NAV Table'!D12 -> 4.653136 | C12: ='Quarterly NAV Table'!E12 -> 29.721104 | D12: ='Valuation & SBG NAV'!BN14 -> 4.653136 | E12: ='Valuation & SBG NAV'!BN58 -> 29.721104 | F12: =D12-B12 -> 0 | G12: =E12-C12 -> 0 | I12: =1000000*F12/FP!$D$6 -> 0
A13: SVF2 | B13: ='Quarterly NAV Table'!D13 -> 13.17 | C13: ='Quarterly NAV Table'!E13 -> 84.121104 | D13: ='Valuation & SBG NAV'!BN15 -> 13.17 | E13: ='Valuation & SBG NAV'!BN59 -> 84.121104 | F13: =D13-B13 -> 0 | G13: =E13-C13 -> 0 | I13: =1000000*F13/FP!$D$6 -> 0
A14: LatAm Funds | B14: ='Quarterly NAV Table'!D14 -> 1.04 | C14: ='Quarterly NAV Table'!E14 -> 6.6428206 | D14: ='Valuation & SBG NAV'!BN16 -> 1.04 | E14: ='Valuation & SBG NAV'!BN60 -> 6.6428206 | F14: =D14-B14 -> 0 | G14: =E14-C14 -> 0 | I14: =1000000*F14/FP!$D$6 -> 0
A15: SBG's equity in Vision Funds | B15: ='Quarterly NAV Table'!D15 -> 18 | C15: ='Quarterly NAV Table'!E15 -> 114.9719 | D15: ='Valuation & SBG NAV'!BN17 -> 18 | E15: ='Valuation & SBG NAV'!BN61 -> 114.9719 | F15: =D15-B15 -> 0 | G15: =E15-C15 -> 0 | I15: =1000000*F15/FP!$D$6 -> 0
A16: T-Mobile US | B16: ='Quarterly NAV Table'!D16 -> 0.91 | C16: ='Quarterly NAV Table'!E16 -> 5.8124681 | D16: ='Valuation & SBG NAV'!BN18 -> 0.91 | E16: ='Valuation & SBG NAV'!BN62 -> 5.8124681 | F16: =D16-B16 -> 0 | G16: =E16-C16 -> 0 | I16: =1000000*F16/FP!$D$6 -> 0
A17: Deutsche Telekom | B17: ='Quarterly NAV Table'!D17 -> 0 | C17: ='Quarterly NAV Table'!E17 -> 0 | D17: ='Valuation & SBG NAV'!BN19 -> 0 | E17: ='Valuation & SBG NAV'!BN63 -> 0 | F17: =D17-B17 -> 0 | G17: =E17-C17 -> 0 | I17: =1000000*F17/FP!$D$6 -> 0
A18: Arm | B18: ='Quarterly NAV Table'!D18 -> 12.69 | C18: ='Quarterly NAV Table'!E18 -> 81.055187 | D18: ='Valuation & SBG NAV'!BN20 -> 12.69 | E18: ='Valuation & SBG NAV'!BN64 -> 81.055187 | F18: =D18-B18 -> 0 | G18: =E18-C18 -> 0 | I18: =1000000*F18/FP!$D$6 -> 0
A19: Others | B19: ='Quarterly NAV Table'!D19 -> 4.46 | C19: ='Quarterly NAV Table'!E19 -> 28.487481 | D19: ='Valuation & SBG NAV'!BN21 -> 4.46 | E19: ='Valuation & SBG NAV'!BN65 -> 28.487481 | F19: =D19-B19 -> 0 | G19: =E19-C19 -> 0 | I19: =1000000*F19/FP!$D$6 -> 0
A20: SBG total value of equity holdings net of asset-backed finance = A | B20: ='Quarterly NAV Table'!D20 -> 38.98 | C20: ='Quarterly NAV Table'!E20 -> 248.97803 | D20: ='Valuation & SBG NAV'!BN22 -> 38.98 | E20: ='Valuation & SBG NAV'!BN66 -> 248.97803 | F20: =D20-B20 -> 0 | G20: =E20-C20 -> 0 | I20: =1000000*F20/FP!$D$6 -> 0
A21: Less: SBG TopCo standalone net interest-bearing debt = B | B21: ='Quarterly NAV Table'!D21 -> 8.04 | C21: ='Quarterly NAV Table'!E21 -> 51.354113 | D21: ='Valuation & SBG NAV'!BN31 -> 8.04 | E21: ='Valuation & SBG NAV'!BN71 -> 51.354113 | F21: =D21-B21 -> 0 | G21: =E21-C21 -> 0 | I21: =1000000*F21/FP!$D$6 -> 0
A22: Net asset value = A - B | B22: ='Quarterly NAV Table'!D22 -> 30.94 | C22: ='Quarterly NAV Table'!E22 -> 197.62391 | D22: =D20-D21 -> 30.94 | E22: =E20-E21 -> 197.62391 | F22: =D22-B22 -> 0 | G22: =E22-C22 -> 0 | I22: =1000000*F22/FP!$D$6 -> 0
A23: per share ¥ | D23: =MROUND(1000000*D22/FP!$D$10, 10) -> 5420
A24: % qoq increase/(decrease) | D24: =D22/B22-1 -> 0 | E24: =E22/C22-1 -> 0
A26: Loan-to-value = B/A | B26: =C21/C20 -> 0.20625962 | D26: =E21/E20 -> 0.20625962
A27: EoP FX | B27: ='Valuation & SBG NAV'!BM79 -> 148.88 | D27: ='Valuation & SBG NAV'!BN79 -> 156.56
A28: % qoq change | D28: =D27/B27-1 -> 0.051585169

Sheet Quarterly NAV Table
A1: SoftBank Group Corp.
A2: year end March ¥tn | I2: Annual
A4: Net asset value & LTV ¥tn = as reported by SBG.
B5: = update quarterly figures by adjusting column refs from Valuation & SBG NAV and delta columns update automatically.
B6: F2Q25 | D6: F3Q25E | F6: delta
B7: ¥tn | C7: $bn | D7: ¥tn | E7: $bn | F7: ¥tn | G7: $bn
A8: Alibaba | B8: ='Valuation & SBG NAV'!BM10 -> 0 | C8: ='Valuation & SBG NAV'!BM54 -> 0 | D8: ='Valuation & SBG NAV'!BN10 -> 0 | E8: ='Valuation & SBG NAV'!BN54 -> 0 | F8: =D8-B8 -> 0 | G8: =E8-C8 -> 0
A9: SoftBank Corp. | B9: ='Valuation & SBG NAV'!BM11 -> 3.37 | C9: ='Valuation & SBG NAV'!BM55 -> 22.63568 | D9: ='Valuation & SBG NAV'!BN11 -> 2.92 | E9: ='Valuation & SBG NAV'!BN55 -> 18.650996 | F9: =D9-B9 -> -0.45 | G9: =E9-C9 -> -3.9846833
A10: SVF1 | B10: ='Valuation & SBG NAV'!BM12 -> 3.96 | C10: ='Valuation & SBG NAV'!BM56 -> 26.598603 | D10: ='Valuation & SBG NAV'!BN12 -> 3.79 | E10: ='Valuation & SBG NAV'!BN56 -> 24.207971 | F10: =D10-B10 -> -0.17 | G10: =E10-C10 -> -2.3906315
A11: OpenAI | B11: ='Valuation & SBG NAV'!BM13 -> 3.677336 | C11: ='Valuation & SBG NAV'!BM57 -> 24.7 | D11: ='Valuation & SBG NAV'!BN13 -> 8.516864 | E11: ='Valuation & SBG NAV'!BN57 -> 54.4 | F11: =D11-B11 -> 4.839528 | G11: =E11-C11 -> 29.7
A12: SVF2 excl. OpenAI | B12: ='Valuation & SBG NAV'!BM14 -> 4.582664 | C12: ='Valuation & SBG NAV'!BM58 -> 30.780924 | D12: ='Valuation & SBG NAV'!BN14 -> 4.653136 | E12: ='Valuation & SBG NAV'!BN58 -> 29.721104 | F12: =D12-B12 -> 0.070472 | G12: =E12-C12 -> -1.0598205
A13: SVF2 | B13: ='Valuation & SBG NAV'!BM15 -> 8.26 | C13: ='Valuation & SBG NAV'!BM59 -> 55.480924 | D13: ='Valuation & SBG NAV'!BN15 -> 13.17 | E13: ='Valuation & SBG NAV'!BN59 -> 84.121104 | F13: =D13-B13 -> 4.91 | G13: =E13-C13 -> 28.640179
A14: LatAm Funds | B14: ='Valuation & SBG NAV'!BM16 -> 1.04 | C14: ='Valuation & SBG NAV'!BM60 -> 6.9854917 | D14: ='Valuation & SBG NAV'!BN16 -> 1.04 | E14: ='Valuation & SBG NAV'!BN60 -> 6.6428206 | F14: =D14-B14 -> 0 | G14: =E14-C14 -> -0.34267103
A15: SBG's equity in Vision Funds | B15: ='Valuation & SBG NAV'!BM17 -> 13.26 | C15: ='Valuation & SBG NAV'!BM61 -> 89.065019 | D15: ='Valuation & SBG NAV'!BN17 -> 18 | E15: ='Valuation & SBG NAV'!BN61 -> 114.9719 | F15: =D15-B15 -> 4.74 | G15: =E15-C15 -> 25.906877
A16: T-Mobile US | B16: ='Valuation & SBG NAV'!BM18 -> 1.61 | C16: ='Valuation & SBG NAV'!BM62 -> 10.814078 | D16: ='Valuation & SBG NAV'!BN18 -> 0.91 | E16: ='Valuation & SBG NAV'!BN62 -> 5.8124681 | F16: =D16-B16 -> -0.7 | G16: =E16-C16 -> -5.0016104
A17: Deutsche Telekom | B17: ='Valuation & SBG NAV'!BM19 -> 0.05 | C17: ='Valuation & SBG NAV'!BM63 -> 0.33584095 | D17: ='Valuation & SBG NAV'!BN19 -> 0 | E17: ='Valuation & SBG NAV'!BN63 -> 0 | F17: =D17-B17 -> -0.05 | G17: =E17-C17 -> -0.33584095
A18: Arm | B18: ='Valuation & SBG NAV'!BM20 -> 18.18 | C18: ='Valuation & SBG NAV'!BM64 -> 122.11177 | D18: ='Valuation & SBG NAV'!BN20 -> 12.69 | E18: ='Valuation & SBG NAV'!BN64 -> 81.055187 | F18: =D18-B18 -> -5.49 | G18: =E18-C18 -> -41.056581
A19: Others | B19: ='Valuation & SBG NAV'!BM21 -> 3.39 | C19: ='Valuation & SBG NAV'!BM65 -> 22.770016 | D19: ='Valuation & SBG NAV'!BN21 -> 4.46 | E19: ='Valuation & SBG NAV'!BN65 -> 28.487481 | F19: =D19-B19 -> 1.07 | G19: =E19-C19 -> 5.7174647
A20: SBG total value of equity holdings net of asset-backed finance = A | B20: ='Valuation & SBG NAV'!BM22 -> 39.86 | C20: ='Valuation & SBG NAV'!BM66 -> 267.7324 | D20: ='Valuation & SBG NAV'!BN22 -> 38.98 | E20: ='Valuation & SBG NAV'!BN66 -> 248.97803 | F20: =D20-B20 -> -0.88 | G20: =E20-C20 -> -18.754374
A21: Less: SBG TopCo standalone net interest-bearing debt = B | B21: ='Valuation & SBG NAV'!BM31 -> 6.56 | C21: ='Valuation & SBG NAV'!BM71 -> 44.062332 | D21: ='Valuation & SBG NAV'!BN31 -> 8.04 | E21: ='Valuation & SBG NAV'!BN71 -> 51.354113 | F21: =D21-B21 -> 1.48 | G21: =E21-C21 -> 7.2917814
A22: Net asset value = A - B | B22: =B20-B21 -> 33.3 | C22: =C20-C21 -> 223.67007 | D22: =D20-D21 -> 30.94 | E22: =E20-E21 -> 197.62391 | F22: =D22-B22 -> -2.36 | G22: =E22-C22 -> -26.046156
A23: per share ¥ | D23: =MROUND(1000000*D22/FP!$D$10, 10) -> 5420
A24: % qoq increase/(decrease) | D24: =D22/B22-1 -> -0.070870871 | E24: =E22/C22-1 -> -0.116449
A26: Loan-to-value = B/A | B26: =C21/C20 -> 0.16457602 | D26: =E21/E20 -> 0.20625962
A27: EoP FX | B27: ='Valuation & SBG NAV'!BM79 -> 148.88 | D27: ='Valuation & SBG NAV'!BN79 -> 156.56
A28: % qoq change | D28: =D27/B27-1 -> 0.051585169

Sheet OpenAI SBG "rough"
B1: Cost $bn | C1: Pre-money $bn | D1: All-in valuation $bn | E1: % | F1: Post-dilution % | G1: Quarter $bn
G3: F2Q $bn
A4: Autumn '24 | B4: 0.5 | C4: =D4-6.6 -> 150.4 | D4: 157 | E4: =100*B4/D4 -> 0.31847134 | F4: =E4*(1-10/300) -> 0.30785563 | G4: =F4*$G$11/100 -> 1.3468684
A5: C1Q | B5: 1.7 | C5: =D5 -> 157 | D5: 157 | E5: =100*B5/D5 -> 1.0828025 | F5: =E5*(1-10/300) -> 1.0467091 | G5: =F5*$G$11/100 -> 4.5793524
A6: #1 tranche | B6: 7.5 | C6: =D6-40 -> 260 | D6: 300 | E6: =100*B6/D6 -> 2.5 | F6: =E6 -> 2.5 | G6: =F6*$G$11/100 -> 10.9375
A7: August | B7: 1.1 | C7: =D7 -> 300 | D7: 300 | E7: =100*B7/D7 -> 0.36666667 | F7: =E7 -> 0.36666667 | G7: =F7*$G$11/100 -> 1.6041667
A8: Total | B8: =SUM(B4:B7) -> 10.8 | C8: =(C4*B4/$B$8)+(C5*B5/$B$8)+(C6*B6/$B$8)+(C7*B7/$B$8) -> 242.78704 | D8: =(D4*B4/$B$8)+(D5*B5/$B$8)+(D6*B6/$B$8)+(D7*B7/$B$8) -> 270.87037 | E8: =SUM(E4:E7) -> 4.2679406 | F8: =SUM(F4:F7) -> 4.2212314 | G8: =SUM(G4:G7) -> 18.467887
A9: "net profit" on OpenAI investment $bn | G9: =G8-B8 -> 7.6678875
A11: OpenAI all-in valuation at F2Q $bn | G11: 437.5 | H11: 500 | I11: = $6.6bn Oct. '25 employee share sale -> $1.45bn participation by SVF2.
A12: % uplift vs. prior $300bn all-in mark | G12: =G11/G20-1 -> 0.86170213 | H12: =1-G11/H11 -> 0.125 | I12: = % discount to publicly reported "mark-to-market".
G14: FY24 $bn
A15: Autumn '24 | B15: 0.5 | C15: =D15-6.6 -> 150.4 | D15: 157 | E15: =100*B15/D15 -> 0.31847134 | F15: =E15 -> 0.31847134 | G15: =F15*$G$20/100 -> 0.74840764
A16: C1Q | B16: 1.7 | C16: =D16 -> 157 | D16: 157 | E16: =100*B16/D16 -> 1.0828025 | F16: =E16 -> 1.0828025 | G16: =F16*$G$20/100 -> 2.544586
A17: Total | B17: =SUM(B15:B16) -> 2.2 | C17: =(C15*B15/$B$17)+(C16*B16/$B$17) -> 155.5 | D17: =(D15*B15/$B$17)+(D16*B16/$B$17) -> 157 | E17: =SUM(E15:E16) -> 1.4012739 | F17: =SUM(F15:F16) -> 1.4012739 | G17: =SUM(G15:G16) -> 3.2929936
A18: "net profit" on OpenAI investment $bn | G18: =G17-B17 -> 1.0929936
A20: OpenAI all-in valuation at FY24 $bn | G20: 235 | H20: 300 | I20: = $40bn CY25 funding round.
A21: % uplift vs. prior $300bn all-in mark | G21: =G20/$D$17-1 -> 0.49681529 | H21: =1-G20/H20 -> 0.21666667 | I21: = % discount to publicly reported "mark-to-market".
G23: F3Q $bn
A24: Autumn '24 | B24: 0.5 | C24: =D24-6.6 -> 150.4 | D24: 157 | E24: =100*B24/D24 -> 0.31847134 | F24: =E24*(1-41/300) -> 0.27494692 | G24: =F24*$G$32/100 -> 1.2372611
A25: C1Q | B25: 1.7 | C25: =D25 -> 157 | D25: 157 | E25: =100*B25/D25 -> 1.0828025 | F25: =E25*(1-41/300) -> 0.93481953 | G25: =F25*$G$32/100 -> 4.2066879
A26: #1 tranche | B26: 7.5 | C26: =D26-40 -> 260 | D26: 300 | E26: =100*B26/D26 -> 2.5 | F26: =E26 -> 2.5 | G26: =F26*$G$32/100 -> 11.25
A27: August | B27: 1.1 | C27: =D27 -> 300 | D27: 300 | E27: =100*B27/D27 -> 0.36666667 | F27: =E27*(1-30/300) -> 0.33 | G27: =F27*$G$32/100 -> 1.485
A28: October | B28: 1.45 | C28: =D28 -> 500 | D28: 500 | E28: =100*B28/D28 -> 0.29 | F28: =E28*(1-30/300) -> 0.261 | G28: =F28*$G$32/100 -> 1.1745
A29: #2 tranche | B29: 22.5 | C29: =D29-40 -> 260 | D29: 300 | E29: =100*B29/D29 -> 7.5 | F29: =E29 -> 7.5 | G29: =F29*$G$32/100 -> 33.75
A30: Total | B30: =SUM(B24:B29) -> 34.75 | C30: =(C24*B24/$B$30)+(C25*B25/$B$30)+(C26*B26/$B$30)+(C27*B27/$B$30)+(C28*B28/$B$30)+(C29*B29/$B$30) -> 264.66475 | D30: =(D24*B24/$B$30)+(D25*B25/$B$30)+(D26*B26/$B$30)+(D27*B27/$B$30)+(D28*B28/$B$30)+(D29*B29/$B$30) -> 299.29209 | E30: =SUM(E24:E29) -> 12.057941 | F30: =SUM(F24:F29) -> 11.800766 | G30: =SUM(G24:G29) -> 53.103449
A32: OpenAI all-in valuation at F3Q $bn | G32: 450
A33: % uplift vs. prior $300bn all-in mark | G33: =G32/G11-1 -> 0.028571429
A35: * $437.5bn estimate of OpenAI all-in valuation for existing stakes at F2Q (i.e., $10.8bn cumulative investments up to August '25) differs from valuation implied by "OpenAI Forward Contract" -> $8bn net profit on $22.5bn "notional" for #2 tranche = 35.5% implied uplift to $406.7bn -> IR guidance is that there is some level of "uncertainty" over $22.5bn Dec. '25 tranche (e.g., via options pricing) written into 30 Sep./F2Q mark, hence the implied all-in mark is different to existing investments.
A37: SVF2 "gain" on OpenAI investment in F3QE ->
A39: SVF2 existing investments | G39: =1000*G8*(G32/G11-1) -> 527.65393
A40: $22.5bn Dec. '25 investment | G40: =1000*(22.5*(G32/300-1)-8) -> 3250 | H40: -> $8bn net profit already recognised = $6.2bn at SVF2 and $1.8bn at "TopCo" or "SBG".
A41: Total SVF2 gain on OpenAI investment in F3Q $m | G41: =SUM(G39:G40) -> 3777.6539
A42: Gain/(loss) on publicly-listed assets | G42: ='SVF2'!AY68-'SVF2'!AX68 -> 1400
A43: Gain/(loss) on OpenAI private assets | G43: 0
A44: Effective SVF2 gain/(loss) in F3Q $m | G44: =SUM(G41:G43) -> 5177.6539
A45: % effective gain/(loss) | G45: =G44/AVERAGE('SVF2'!$AX$10:$AY$10) -> 0.072566979
A47: SVF2 "gain" on OpenAI investment in F3QE assuming OpenAI to $500bn all-in valuation ->
A49: SVF2 existing investments | G49: =1000*G8*(500/G11-1) -> 2638.2696
A50: $22.5bn Dec. '25 investment | G50: =1000*(22.5*(500/300-1)-8) -> 7000
A51: Total SVF2 gain on OpenAI investment in F3Q $m | G51: =SUM(G49:G50) -> 9638.2696
...

Sheet OpenAI Valuation table
B1: Cost $bn | C1: Pre-money $bn | D1: Post-money $bn | E1: % | F1: Diluted % | G1: F2Q $bn | H1: F3QE $bn | K1: 11.8 | L1: 11.5 | M1: 11 | O1: OpenAI PBC dilution from all-equity acquisitions + third-party investments (e.g., Disney) ->
A2: Autumn '24 | B2: ='OpenAI SBG "rough"'!B24 -> 0.5 | C2: ='OpenAI SBG "rough"'!C24 -> 150.4 | D2: ='OpenAI SBG "rough"'!D24 -> 157 | E2: ='OpenAI SBG "rough"'!E24 -> 0.31847134 | F2: ='OpenAI SBG "rough"'!F24 -> 0.27494692 | G2: ='OpenAI SBG "rough"'!G4 -> 1.3468684 | H2: ='OpenAI SBG "rough"'!G24 -> 1.2372611 | K2: =H2*$K$15/$H$15 -> 1.2785032 | L2: =($L$1/$F$14)*H2*$L$15/$H$15 -> 1.2727119 | M2: =($M$1/$F$14)*H2*$M$15/$H$15 -> 1.281449 | O2: Company | P2: Date | Q2: Transaction | R2: Valuation | S2: OAI all-in | T2: % dilution | V2: Comments ->
A3: C1Q | B3: ='OpenAI SBG "rough"'!B25 -> 1.7 | C3: ='OpenAI SBG "rough"'!C25 -> 157 | D3: ='OpenAI SBG "rough"'!D25 -> 157 | E3: ='OpenAI SBG "rough"'!E25 -> 1.0828025 | F3: ='OpenAI SBG "rough"'!F25 -> 0.93481953 | G3: ='OpenAI SBG "rough"'!G5 -> 4.5793524 | H3: ='OpenAI SBG "rough"'!G25 -> 4.2066879 | K3: =H3*$K$15/$H$15 -> 4.3469108 | L3: =($L$1/$F$14)*H3*$L$15/$H$15 -> 4.3272204 | M3: =($M$1/$F$14)*H3*$M$15/$H$15 -> 4.3569267 | O3: io | P3: May '25 | Q3: Acquired | R3: 6.5 | S3: 300 | T3: =R3/S3 -> 0.021666667
